Errore: (raised as a result of Query-invoked autoflush; consider using a session.no_autoflush block if this flush is occurring prematurely) (psycopg2.errors.CannotCoerce) cannot cast type time without time zone to timestamp without time zone LINE 1: ...ype) SELECT p0::INTEGER, p1::DATE, p2::VARCHAR, p3::TIMESTAM... ^ [SQL: INSERT INTO attendance_event (user_id, date, event_type, timestamp, sede_id, commessa_id, notes, shift_status, created_at, company_id, is_manual, entry_type) SELECT p0::INTEGER, p1::DATE, p2::VARCHAR, p3::TIMESTAMP WITHOUT TIME ZONE, p4::INTEGER, p5: ... 1041 characters truncated ... , p11, sen_counter) ORDER BY sen_counter RETURNING attendance_event.id, attendance_event.id AS id__1] [parameters: {'user_id__0': 4, 'timestamp__0': datetime.time(9, 0), 'notes__0': None, 'event_type__0': 'clock_in', 'created_at__0': datetime.datetime(2025, 10, 28, 11, 29, 9, 648797, tzinfo=zoneinfo.ZoneInfo(key='Europe/Rome')), 'date__0': datetime.date(2025, 9, 1), 'company_id__0': 1, 'entry_type__0': 'standard', 'is_manual__0': True, 'commessa_id__0': 1, 'shift_status__0': None, 'sede_id__0': 1, 'user_id__1': 4, 'timestamp__1': datetime.time(13, 0), 'notes__1': None, 'event_type__1': 'break_start', 'created_at__1': datetime.datetime(2025, 10, 28, 11, 29, 9, 648803, tzinfo=zoneinfo.ZoneInfo(key='Europe/Rome')), 'date__1': datetime.date(2025, 9, 1), 'company_id__1': 1, 'entry_type__1': 'standard', 'is_manual__1': True, 'commessa_id__1': 1, 'shift_status__1': None, 'sede_id__1': 1, 'user_id__2': 4, 'timestamp__2': datetime.time(14, 0), 'notes__2': None, 'event_type__2': 'break_end', 'created_at__2': datetime.datetime(2025, 10, 28, 11, 29, 9, 648804, tzinfo=zoneinfo.ZoneInfo(key='Europe/Rome')), 'date__2': datetime.date(2025, 9, 1), 'company_id__2': 1, 'entry_type__2': 'standard', 'is_manual__2': True, 'commessa_id__2': 1, 'shift_status__2': None, 'sede_id__2': 1, 'user_id__3': 4, 'timestamp__3': datetime.time(18, 0), 'notes__3': None, 'event_type__3': 'clock_out', 'created_at__3': datetime.datetime(2025, 10, 28, 11, 29, 9, 648806, tzinfo=zoneinfo.ZoneInfo(key='Europe/Rome')), 'date__3': datetime.date(2025, 9, 1), 'company_id__3': 1, 'entry_type__3': 'standard', 'is_manual__3': True, 'commessa_id__3': 1, 'shift_status__3': None, 'sede_id__3': 1}] (Background on this error at: https://sqlalche.me/e/20/f405)